<sdf version='1.6'>
  <world name='default'>
    <model name='ground_plane'>
      <static>1</static>
      <link name='link'>
        <collision name='collision'>
          <geometry>
            <plane>
              <normal>0 0 1</normal>
              <size>100 100</size>
            </plane>
          </geometry>
          <surface>
            <friction>
              <ode>
                <mu>100</mu>
                <mu2>50</mu2>
              </ode>
              <torsional>
                <ode/>
              </torsional>
            </friction>
            <contact>
              <ode/>
            </contact>
            <bounce/>
          </surface>
          <max_contacts>10</max_contacts>
        </collision>
        <visual name='visual'>
          <cast_shadows>0</cast_shadows>
          <geometry>
            <plane>
              <normal>0 0 1</normal>
              <size>100 100</size>
            </plane>
          </geometry>
          <material>
            <script>
              <uri>file://media/materials/scripts/gazebo.material</uri>
              <name>Gazebo/Grey</name>
            </script>
          </material>
        </visual>
        <self_collide>0</self_collide>
        <kinematic>0</kinematic>
      </link>
    </model>
    <light name='sun' type='directional'>
      <cast_shadows>1</cast_shadows>
      <pose frame=''>0 0 10 0 -0 0</pose>
      <diffuse>0.8 0.8 0.8 1</diffuse>
      <specular>0.2 0.2 0.2 1</specular>
      <attenuation>
        <range>1000</range>
        <constant>0.9</constant>
        <linear>0.01</linear>
        <quadratic>0.001</quadratic>
      </attenuation>
      <direction>-0.5 0.1 -0.9</direction>
    </light>
    <plugin name='ros_interface_plugin' filename='librotors_gazebo_ros_interface_plugin.so'/>
    <spherical_coordinates>
      <surface_model>EARTH_WGS84</surface_model>
      <latitude_deg>47.3667</latitude_deg>
      <longitude_deg>8.55</longitude_deg>
      <elevation>500</elevation>
      <heading_deg>0</heading_deg>
    </spherical_coordinates>
    <physics name='default_physics' default='0' type='ode'>
      <ode>
        <solver>
          <type>quick</type>
          <iters>1000</iters>
          <sor>1.3</sor>
          <use_dynamic_moi_rescaling>0</use_dynamic_moi_rescaling>
        </solver>
        <constraints>
          <cfm>0</cfm>
          <erp>0.2</erp>
          <contact_max_correcting_vel>100</contact_max_correcting_vel>
          <contact_surface_layer>0.001</contact_surface_layer>
        </constraints>
      </ode>
      <max_step_size>0.01</max_step_size>
      <real_time_factor>1</real_time_factor>
      <real_time_update_rate>100</real_time_update_rate>
    </physics>
    <gravity>0 0 -9.8</gravity>
    <magnetic_field>6e-06 2.3e-05 -4.2e-05</magnetic_field>
    <atmosphere type='adiabatic'/>
    <scene>
      <ambient>0.4 0.4 0.4 1</ambient>
      <background>0.7 0.7 0.7 1</background>
      <shadows>1</shadows>
    </scene>
    <model name='bebop2'>
      <link name='bebop2/base_link'>
        <pose frame=''>0 0 0 0 -0 0</pose>
        <inertial>
          <pose frame=''>2e-06 0 0 0 -0 0</pose>
          <mass>0.50301</mass>
          <inertia>
            <ixx>0.001806</ixx>
            <ixy>-8.619e-07</ixy>
            <ixz>1.555e-05</ixz>
            <iyy>0.0017651</iyy>
            <iyz>3.595e-07</iyz>
            <izz>0.0033291</izz>
          </inertia>
        </inertial>
        <collision name='bebop2/base_link_inertia_collision'>
          <pose frame=''>0 0 0 0 -0 0</pose>
          <geometry>
            <box>
              <size>0.316618 0.316618 0.089582</size>
            </box>
          </geometry>
          <max_contacts>10</max_contacts>
          <surface>
            <contact>
              <ode/>
            </contact>
            <bounce/>
            <friction>
              <torsional>
                <ode/>
              </torsional>
              <ode/>
            </friction>
          </surface>
        </collision>
        <collision name='bebop2/base_link_fixed_joint_lump__bebop2/camera_base_link_collision_1'>
          <pose frame=''>0.1 0 0 0 -0 0</pose>
          <geometry>
            <box>
              <size>0.001 0.001 0.001</size>
            </box>
          </geometry>
          <surface>
            <contact>
              <ode/>
            </contact>
            <friction>
              <ode/>
              <torsional>
                <ode/>
              </torsional>
            </friction>
            <bounce/>
          </surface>
          <max_contacts>10</max_contacts>
        </collision>
        <visual name='bebop2/base_link_inertia_visual'>
          <pose frame=''>0 0 0 0 -0 0</pose>
          <geometry>
            <mesh>
              <scale>1 1 1</scale>
              <uri>/home/subbu/catkin_ws/src/rotors_simulator/rotors_description/meshes/bebop2.dae</uri>
            </mesh>
          </geometry>
        </visual>
        <visual name='bebop2/base_link_fixed_joint_lump__bebop2/camera_base_link_visual_1'>
          <pose frame=''>0.1 0 0 -3e-06 1.57079 -3e-06</pose>
          <geometry>
            <box>
              <size>0.001 0.001 0.001</size>
            </box>
          </geometry>
          <material>
            <script>
              <uri>__default__</uri>
              <name>__default__</name>
            </script>
          </material>
        </visual>
        <gravity>1</gravity>
        <velocity_decay/>
        <sensor name='bebop2_camera_base' type='camera'>
          <update_rate>30</update_rate>
          <camera name='head'>
            <horizontal_fov>1.7</horizontal_fov>
            <image>
              <width>856</width>
              <height>480</height>
              <format>R8G8B8</format>
            </image>
            <clip>
              <near>0.02</near>
              <far>50</far>
            </clip>
            <noise>
              <type>gaussian</type>
              <mean>0</mean>
              <stddev>0.007</stddev>
            </noise>
          </camera>
          <plugin name='bebop2_camera_base_controller' filename='libgazebo_ros_camera.so'>
            <robotNamespace>bebop2</robotNamespace>
            <alwaysOn>true</alwaysOn>
            <updateRate>30.0</updateRate>
            <cameraName>camera_base</cameraName>
            <imageTopicName>image_raw</imageTopicName>
            <cameraInfoTopicName>camera_info</cameraInfoTopicName>
            <frameName>camera_base_link</frameName>
            <hackBaseline>0.0</hackBaseline>
            <distortionK1>0.0</distortionK1>
            <distortionK2>0.0</distortionK2>
            <distortionK3>0.0</distortionK3>
            <distortionT1>0.0</distortionT1>
            <distortionT2>0.0</distortionT2>
          </plugin>
          <pose frame=''>0.1 0 0 0 -0 0</pose>
        </sensor>
        <self_collide>0</self_collide>
        <kinematic>0</kinematic>
      </link>
      <link name='bebop2/imu_link'>
        <pose frame=''>0 0 0 0 -0 0</pose>
        <inertial>
          <pose frame=''>0 0 0 0 -0 0</pose>
          <mass>0.015</mass>
          <inertia>
            <ixx>1e-05</ixx>
            <ixy>0</ixy>
            <ixz>0</ixz>
            <iyy>1e-05</iyy>
            <iyz>0</iyz>
            <izz>1e-05</izz>
          </inertia>
        </inertial>
        <self_collide>0</self_collide>
        <kinematic>0</kinematic>
      </link>
      <joint name='bebop2/imu_joint' type='revolute'>
        <child>bebop2/imu_link</child>
        <parent>bebop2/base_link</parent>
        <axis>
          <xyz>1 0 0</xyz>
          <limit>
            <lower>0</lower>
            <upper>0</upper>
            <effort>0</effort>
            <velocity>0</velocity>
          </limit>
          <dynamics>
            <spring_reference>0</spring_reference>
            <spring_stiffness>0</spring_stiffness>
          </dynamics>
          <use_parent_model_frame>1</use_parent_model_frame>
        </axis>
      </joint>
      <link name='bebop2/imugt_link'>
        <pose frame=''>0 0 0 0 -0 0</pose>
        <inertial>
          <pose frame=''>0 0 0 0 -0 0</pose>
          <mass>1e-05</mass>
          <inertia>
            <ixx>1e-05</ixx>
            <ixy>0</ixy>
            <ixz>0</ixz>
            <iyy>1e-05</iyy>
            <iyz>0</iyz>
            <izz>1e-05</izz>
          </inertia>
        </inertial>
        <self_collide>0</self_collide>
        <kinematic>0</kinematic>
      </link>
      <joint name='bebop2/imugt_joint' type='revolute'>
        <child>bebop2/imugt_link</child>
        <parent>bebop2/base_link</parent>
        <axis>
          <xyz>1 0 0</xyz>
          <limit>
            <lower>0</lower>
            <upper>0</upper>
            <effort>0</effort>
            <velocity>0</velocity>
          </limit>
          <dynamics>
            <spring_reference>0</spring_reference>
            <spring_stiffness>0</spring_stiffness>
          </dynamics>
          <use_parent_model_frame>1</use_parent_model_frame>
        </axis>
      </joint>
      <link name='bebop2/odometry_sensor1_link'>
        <pose frame=''>0 0 0 0 -0 0</pose>
        <inertial>
          <pose frame=''>0 0 0 0 -0 0</pose>
          <mass>1e-05</mass>
          <inertia>
            <ixx>1e-05</ixx>
            <ixy>0</ixy>
            <ixz>0</ixz>
            <iyy>1e-05</iyy>
            <iyz>0</iyz>
            <izz>1e-05</izz>
          </inertia>
        </inertial>
        <self_collide>0</self_collide>
        <kinematic>0</kinematic>
      </link>
      <joint name='bebop2/odometry_sensor1_joint' type='revolute'>
        <child>bebop2/odometry_sensor1_link</child>
        <parent>bebop2/base_link</parent>
        <axis>
          <xyz>1 0 0</xyz>
          <limit>
            <lower>0</lower>
            <upper>0</upper>
            <effort>0</effort>
            <velocity>0</velocity>
          </limit>
          <dynamics>
            <spring_reference>0</spring_reference>
            <spring_stiffness>0</spring_stiffness>
          </dynamics>
          <use_parent_model_frame>1</use_parent_model_frame>
        </axis>
      </joint>
      <link name='bebop2/odometry_sensorgt_link'>
        <pose frame=''>0 0 0 0 -0 0</pose>
        <inertial>
          <pose frame=''>0 0 0 0 -0 0</pose>
          <mass>1e-05</mass>
          <inertia>
            <ixx>1e-05</ixx>
            <ixy>0</ixy>
            <ixz>0</ixz>
            <iyy>1e-05</iyy>
            <iyz>0</iyz>
            <izz>1e-05</izz>
          </inertia>
        </inertial>
        <self_collide>0</self_collide>
        <kinematic>0</kinematic>
      </link>
      <joint name='bebop2/odometry_sensorgt_joint' type='revolute'>
        <child>bebop2/odometry_sensorgt_link</child>
        <parent>bebop2/base_link</parent>
        <axis>
          <xyz>1 0 0</xyz>
          <limit>
            <lower>0</lower>
            <upper>0</upper>
            <effort>0</effort>
            <velocity>0</velocity>
          </limit>
          <dynamics>
            <spring_reference>0</spring_reference>
            <spring_stiffness>0</spring_stiffness>
          </dynamics>
          <use_parent_model_frame>1</use_parent_model_frame>
        </axis>
      </joint>
      <link name='bebop2/rotor_0'>
        <pose frame=''>0.08456 -0.11435 -0.00501 0 -0 0</pose>
        <inertial>
          <pose frame=''>0 0 0 0 -0 0</pose>
          <mass>0.001</mass>
          <inertia>
            <ixx>1.95e-07</ixx>
            <ixy>0</ixy>
            <ixz>0</ixz>
            <iyy>8.34083e-06</iyy>
            <iyz>0</iyz>
            <izz>8.52083e-06</izz>
          </inertia>
        </inertial>
        <collision name='bebop2/rotor_0_collision'>
          <pose frame=''>0 0 0 0 -0 0</pose>
          <geometry>
            <cylinder>
              <length>0.005</length>
              <radius>0.1</radius>
            </cylinder>
          </geometry>
          <surface>
            <contact>
              <ode/>
            </contact>
            <friction>
              <ode/>
              <torsional>
                <ode/>
              </torsional>
            </friction>
            <bounce/>
          </surface>
          <max_contacts>10</max_contacts>
        </collision>
        <visual name='bebop2/rotor_0_visual'>
          <pose frame=''>0 0 0 0 -0 0</pose>
          <geometry>
            <mesh>
              <scale>1 1 1</scale>
              <uri>/home/subbu/catkin_ws/src/rotors_simulator/rotors_description/meshes/propeller_fr.dae</uri>
            </mesh>
          </geometry>
          <material>
            <script>
              <name>Gazebo/</name>
              <uri>file://media/materials/scripts/gazebo.material</uri>
            </script>
          </material>
        </visual>
        <gravity>1</gravity>
        <velocity_decay/>
        <self_collide>0</self_collide>
        <kinematic>0</kinematic>
      </link>
      <joint name='bebop2/rotor_0_joint' type='revolute'>
        <child>bebop2/rotor_0</child>
        <parent>bebop2/base_link</parent>
        <axis>
          <xyz>0 0 1</xyz>
          <limit>
            <lower>-1e+16</lower>
            <upper>1e+16</upper>
          </limit>
          <dynamics>
            <spring_reference>0</spring_reference>
            <spring_stiffness>0</spring_stiffness>
          </dynamics>
          <use_parent_model_frame>1</use_parent_model_frame>
        </axis>
      </joint>
      <link name='bebop2/rotor_1'>
        <pose frame=''>-0.09035 0.11452 -0.00501 0 -0 0</pose>
        <inertial>
          <pose frame=''>0 0 0 0 -0 0</pose>
          <mass>0.001</mass>
          <inertia>
            <ixx>1.95e-07</ixx>
            <ixy>0</ixy>
            <ixz>0</ixz>
            <iyy>8.34083e-06</iyy>
            <iyz>0</iyz>
            <izz>8.52083e-06</izz>
          </inertia>
        </inertial>
        <collision name='bebop2/rotor_1_collision'>
          <pose frame=''>0 0 0 0 -0 0</pose>
          <geometry>
            <cylinder>
              <length>0.005</length>
              <radius>0.1</radius>
            </cylinder>
          </geometry>
          <surface>
            <contact>
              <ode/>
            </contact>
            <friction>
              <ode/>
              <torsional>
                <ode/>
              </torsional>
            </friction>
            <bounce/>
          </surface>
          <max_contacts>10</max_contacts>
        </collision>
        <visual name='bebop2/rotor_1_visual'>
          <pose frame=''>0 0 0 0 -0 0</pose>
          <geometry>
            <mesh>
              <scale>1 1 1</scale>
              <uri>/home/subbu/catkin_ws/src/rotors_simulator/rotors_description/meshes/propeller_rl.dae</uri>
            </mesh>
          </geometry>
          <material>
            <script>
              <name>Gazebo/</name>
              <uri>file://media/materials/scripts/gazebo.material</uri>
            </script>
          </material>
        </visual>
        <gravity>1</gravity>
        <velocity_decay/>
        <self_collide>0</self_collide>
        <kinematic>0</kinematic>
      </link>
      <joint name='bebop2/rotor_1_joint' type='revolute'>
        <child>bebop2/rotor_1</child>
        <parent>bebop2/base_link</parent>
        <axis>
          <xyz>0 0 1</xyz>
          <limit>
            <lower>-1e+16</lower>
            <upper>1e+16</upper>
          </limit>
          <dynamics>
            <spring_reference>0</spring_reference>
            <spring_stiffness>0</spring_stiffness>
          </dynamics>
          <use_parent_model_frame>1</use_parent_model_frame>
        </axis>
      </joint>
      <link name='bebop2/rotor_2'>
        <pose frame=''>0.08456 0.11463 -0.00501 0 -0 0</pose>
        <inertial>
          <pose frame=''>0 0 0 0 -0 0</pose>
          <mass>0.001</mass>
          <inertia>
            <ixx>1.95e-07</ixx>
            <ixy>0</ixy>
            <ixz>0</ixz>
            <iyy>8.34083e-06</iyy>
            <iyz>0</iyz>
            <izz>8.52083e-06</izz>
          </inertia>
        </inertial>
        <collision name='bebop2/rotor_2_collision'>
          <pose frame=''>0 0 0 0 -0 0</pose>
          <geometry>
            <cylinder>
              <length>0.005</length>
              <radius>0.1</radius>
            </cylinder>
          </geometry>
          <surface>
            <contact>
              <ode/>
            </contact>
            <friction>
              <ode/>
              <torsional>
                <ode/>
              </torsional>
            </friction>
            <bounce/>
          </surface>
          <max_contacts>10</max_contacts>
        </collision>
        <visual name='bebop2/rotor_2_visual'>
          <pose frame=''>0 0 0 0 -0 0</pose>
          <geometry>
            <mesh>
              <scale>1 1 1</scale>
              <uri>/home/subbu/catkin_ws/src/rotors_simulator/rotors_description/meshes/propeller_fl.dae</uri>
            </mesh>
          </geometry>
          <material>
            <script>
              <name>Gazebo/</name>
              <uri>file://media/materials/scripts/gazebo.material</uri>
            </script>
          </material>
        </visual>
        <gravity>1</gravity>
        <velocity_decay/>
        <self_collide>0</self_collide>
        <kinematic>0</kinematic>
      </link>
      <joint name='bebop2/rotor_2_joint' type='revolute'>
        <child>bebop2/rotor_2</child>
        <parent>bebop2/base_link</parent>
        <axis>
          <xyz>0 0 1</xyz>
          <limit>
            <lower>-1e+16</lower>
            <upper>1e+16</upper>
          </limit>
          <dynamics>
            <spring_reference>0</spring_reference>
            <spring_stiffness>0</spring_stiffness>
          </dynamics>
          <use_parent_model_frame>1</use_parent_model_frame>
        </axis>
      </joint>
      <link name='bebop2/rotor_3'>
        <pose frame=''>-0.09035 -0.11423 -0.00501 0 -0 0</pose>
        <inertial>
          <pose frame=''>0 0 0 0 -0 0</pose>
          <mass>0.001</mass>
          <inertia>
            <ixx>1.95e-07</ixx>
            <ixy>0</ixy>
            <ixz>0</ixz>
            <iyy>8.34083e-06</iyy>
            <iyz>0</iyz>
            <izz>8.52083e-06</izz>
          </inertia>
        </inertial>
        <collision name='bebop2/rotor_3_collision'>
          <pose frame=''>0 0 0 0 -0 0</pose>
          <geometry>
            <cylinder>
              <length>0.005</length>
              <radius>0.1</radius>
            </cylinder>
          </geometry>
          <surface>
            <contact>
              <ode/>
            </contact>
            <friction>
              <ode/>
              <torsional>
                <ode/>
              </torsional>
            </friction>
            <bounce/>
          </surface>
          <max_contacts>10</max_contacts>
        </collision>
        <visual name='bebop2/rotor_3_visual'>
          <pose frame=''>0 0 0 0 -0 0</pose>
          <geometry>
            <mesh>
              <scale>1 1 1</scale>
              <uri>/home/subbu/catkin_ws/src/rotors_simulator/rotors_description/meshes/propeller_rr.dae</uri>
            </mesh>
          </geometry>
          <material>
            <script>
              <name>Gazebo/</name>
              <uri>file://media/materials/scripts/gazebo.material</uri>
            </script>
          </material>
        </visual>
        <gravity>1</gravity>
        <velocity_decay/>
        <self_collide>0</self_collide>
        <kinematic>0</kinematic>
      </link>
      <joint name='bebop2/rotor_3_joint' type='revolute'>
        <child>bebop2/rotor_3</child>
        <parent>bebop2/base_link</parent>
        <axis>
          <xyz>0 0 1</xyz>
          <limit>
            <lower>-1e+16</lower>
            <upper>1e+16</upper>
          </limit>
          <dynamics>
            <spring_reference>0</spring_reference>
            <spring_stiffness>0</spring_stiffness>
          </dynamics>
          <use_parent_model_frame>1</use_parent_model_frame>
        </axis>
      </joint>
      <plugin name='multirotor_base_plugin' filename='librotors_gazebo_multirotor_base_plugin.so'>
        <robotNamespace>bebop2</robotNamespace>
        <linkName>bebop2/base_link</linkName>
        <rotorVelocitySlowdownSim>10</rotorVelocitySlowdownSim>
      </plugin>
      <plugin name='bebop2_front_right_motor_model' filename='librotors_gazebo_motor_model.so'>
        <robotNamespace>bebop2</robotNamespace>
        <jointName>bebop2/rotor_0_joint</jointName>
        <linkName>bebop2/rotor_0</linkName>
        <turningDirection>ccw</turningDirection>
        <timeConstantUp>0.0125</timeConstantUp>
        <timeConstantDown>0.025</timeConstantDown>
        <maxRotVelocity>838</maxRotVelocity>
        <motorConstant>8.54858e-06</motorConstant>
        <momentConstant>0.016</momentConstant>
        <commandSubTopic>gazebo/command/motor_speed</commandSubTopic>
        <motorNumber>0</motorNumber>
        <rotorDragCoefficient>8.06428e-05</rotorDragCoefficient>
        <rollingMomentCoefficient>1e-06</rollingMomentCoefficient>
        <motorSpeedPubTopic>motor_speed/0</motorSpeedPubTopic>
        <rotorVelocitySlowdownSim>10</rotorVelocitySlowdownSim>
      </plugin>
      <plugin name='bebop2_back_left_motor_model' filename='librotors_gazebo_motor_model.so'>
        <robotNamespace>bebop2</robotNamespace>
        <jointName>bebop2/rotor_1_joint</jointName>
        <linkName>bebop2/rotor_1</linkName>
        <turningDirection>ccw</turningDirection>
        <timeConstantUp>0.0125</timeConstantUp>
        <timeConstantDown>0.025</timeConstantDown>
        <maxRotVelocity>838</maxRotVelocity>
        <motorConstant>8.54858e-06</motorConstant>
        <momentConstant>0.016</momentConstant>
        <commandSubTopic>gazebo/command/motor_speed</commandSubTopic>
        <motorNumber>1</motorNumber>
        <rotorDragCoefficient>8.06428e-05</rotorDragCoefficient>
        <rollingMomentCoefficient>1e-06</rollingMomentCoefficient>
        <motorSpeedPubTopic>motor_speed/1</motorSpeedPubTopic>
        <rotorVelocitySlowdownSim>10</rotorVelocitySlowdownSim>
      </plugin>
      <plugin name='bebop2_front_left_motor_model' filename='librotors_gazebo_motor_model.so'>
        <robotNamespace>bebop2</robotNamespace>
        <jointName>bebop2/rotor_2_joint</jointName>
        <linkName>bebop2/rotor_2</linkName>
        <turningDirection>cw</turningDirection>
        <timeConstantUp>0.0125</timeConstantUp>
        <timeConstantDown>0.025</timeConstantDown>
        <maxRotVelocity>838</maxRotVelocity>
        <motorConstant>8.54858e-06</motorConstant>
        <momentConstant>0.016</momentConstant>
        <commandSubTopic>gazebo/command/motor_speed</commandSubTopic>
        <motorNumber>2</motorNumber>
        <rotorDragCoefficient>8.06428e-05</rotorDragCoefficient>
        <rollingMomentCoefficient>1e-06</rollingMomentCoefficient>
        <motorSpeedPubTopic>motor_speed/2</motorSpeedPubTopic>
        <rotorVelocitySlowdownSim>10</rotorVelocitySlowdownSim>
      </plugin>
      <plugin name='bebop2_back_right_motor_model' filename='librotors_gazebo_motor_model.so'>
        <robotNamespace>bebop2</robotNamespace>
        <jointName>bebop2/rotor_3_joint</jointName>
        <linkName>bebop2/rotor_3</linkName>
        <turningDirection>cw</turningDirection>
        <timeConstantUp>0.0125</timeConstantUp>
        <timeConstantDown>0.025</timeConstantDown>
        <maxRotVelocity>838</maxRotVelocity>
        <motorConstant>8.54858e-06</motorConstant>
        <momentConstant>0.016</momentConstant>
        <commandSubTopic>gazebo/command/motor_speed</commandSubTopic>
        <motorNumber>3</motorNumber>
        <rotorDragCoefficient>8.06428e-05</rotorDragCoefficient>
        <rollingMomentCoefficient>1e-06</rollingMomentCoefficient>
        <motorSpeedPubTopic>motor_speed/3</motorSpeedPubTopic>
        <rotorVelocitySlowdownSim>10</rotorVelocitySlowdownSim>
      </plugin>
      <plugin name='controller_interface' filename='librotors_gazebo_controller_interface.so'>
        <robotNamespace>bebop2</robotNamespace>
        <commandAttitudeThrustSubTopic>command/attitude</commandAttitudeThrustSubTopic>
        <commandRateThrustSubTopic>command/rate</commandRateThrustSubTopic>
        <commandMotorSpeedSubTopic>command/motor_speed</commandMotorSpeedSubTopic>
        <imuSubTopic>imu</imuSubTopic>
        <motorSpeedCommandPubTopic>gazebo/command/motor_speed</motorSpeedCommandPubTopic>
      </plugin>
      <plugin name='rotors_gazebo_imu_plugin' filename='librotors_gazebo_imu_plugin.so'>
        <robotNamespace>bebop2</robotNamespace>
        <linkName>bebop2/imu_link</linkName>
        <imuTopic>imu</imuTopic>
        <gyroscopeNoiseDensity>0.0003394</gyroscopeNoiseDensity>
        <gyroscopeRandomWalk>3.8785e-05</gyroscopeRandomWalk>
        <gyroscopeBiasCorrelationTime>1000.0</gyroscopeBiasCorrelationTime>
        <gyroscopeTurnOnBiasSigma>0.0087</gyroscopeTurnOnBiasSigma>
        <accelerometerNoiseDensity>0.004</accelerometerNoiseDensity>
        <accelerometerRandomWalk>0.006</accelerometerRandomWalk>
        <accelerometerBiasCorrelationTime>300.0</accelerometerBiasCorrelationTime>
        <accelerometerTurnOnBiasSigma>0.196</accelerometerTurnOnBiasSigma>
      </plugin>
      <plugin name='rotors_gazebo_imugt_plugin' filename='librotors_gazebo_imu_plugin.so'>
        <robotNamespace>bebop2</robotNamespace>
        <linkName>bebop2/imugt_link</linkName>
        <imuTopic>ground_truth/imu</imuTopic>
        <gyroscopeNoiseDensity>0.0</gyroscopeNoiseDensity>
        <gyroscopeRandomWalk>0.0</gyroscopeRandomWalk>
        <gyroscopeBiasCorrelationTime>1000.0</gyroscopeBiasCorrelationTime>
        <gyroscopeTurnOnBiasSigma>0.0</gyroscopeTurnOnBiasSigma>
        <accelerometerNoiseDensity>0.0</accelerometerNoiseDensity>
        <accelerometerRandomWalk>0.0</accelerometerRandomWalk>
        <accelerometerBiasCorrelationTime>300.0</accelerometerBiasCorrelationTime>
        <accelerometerTurnOnBiasSigma>0.0</accelerometerTurnOnBiasSigma>
      </plugin>
      <plugin name='odometry_sensorgt' filename='librotors_gazebo_odometry_plugin.so'>
        <linkName>bebop2/odometry_sensorgt_link</linkName>
        <robotNamespace>bebop2</robotNamespace>
        <poseTopic>ground_truth/pose</poseTopic>
        <poseWithCovarianceTopic>ground_truth/pose_with_covariance</poseWithCovarianceTopic>
        <positionTopic>ground_truth/position</positionTopic>
        <transformTopic>ground_truth/transform</transformTopic>
        <odometryTopic>ground_truth/odometry</odometryTopic>
        <parentFrameId>world</parentFrameId>
        <childFrameId>bebop2/base_link</childFrameId>
        <measurementDivisor>1</measurementDivisor>
        <measurementDelay>0</measurementDelay>
        <unknownDelay>0.0</unknownDelay>
        <noiseNormalPosition>0 0 0</noiseNormalPosition>
        <noiseNormalQuaternion>0 0 0</noiseNormalQuaternion>
        <noiseNormalLinearVelocity>0 0 0</noiseNormalLinearVelocity>
        <noiseNormalAngularVelocity>0 0 0</noiseNormalAngularVelocity>
        <noiseUniformPosition>0 0 0</noiseUniformPosition>
        <noiseUniformQuaternion>0 0 0</noiseUniformQuaternion>
        <noiseUniformLinearVelocity>0 0 0</noiseUniformLinearVelocity>
        <noiseUniformAngularVelocity>0 0 0</noiseUniformAngularVelocity>
      </plugin>
      <static>0</static>
      <plugin name='odometry_sensor1' filename='librotors_gazebo_odometry_plugin.so'>
        <linkName>bebop2/odometry_sensor1_link</linkName>
        <robotNamespace>bebop2</robotNamespace>
        <poseTopic>odometry_sensor1/pose</poseTopic>
        <poseWithCovarianceTopic>odometry_sensor1/pose_with_covariance</poseWithCovarianceTopic>
        <positionTopic>odometry_sensor1/position</positionTopic>
        <transformTopic>odometry_sensor1/transform</transformTopic>
        <odometryTopic>odometry_sensor1/odometry</odometryTopic>
        <parentFrameId>world</parentFrameId>
        <childFrameId>bebop2/odometry_sensor1</childFrameId>
        <measurementDivisor>1</measurementDivisor>
        <measurementDelay>0</measurementDelay>
        <unknownDelay>0.0</unknownDelay>
        <noiseNormalPosition>0 0 0</noiseNormalPosition>
        <noiseNormalQuaternion>0 0 0</noiseNormalQuaternion>
        <noiseNormalLinearVelocity>0 0 0</noiseNormalLinearVelocity>
        <noiseNormalAngularVelocity>0 0 0</noiseNormalAngularVelocity>
        <noiseUniformPosition>0 0 0</noiseUniformPosition>
        <noiseUniformQuaternion>0 0 0</noiseUniformQuaternion>
        <noiseUniformLinearVelocity>0 0 0</noiseUniformLinearVelocity>
        <noiseUniformAngularVelocity>0 0 0</noiseUniformAngularVelocity>
      </plugin>
      <pose frame=''>0 0 0.1 0 -0 0</pose>
    </model>
    <model name='Marker39'>
      <static>1</static>
      <link name='link'>
        <visual name='visual'>
          <geometry>
            <mesh>
              <uri>model://marker39/meshes/Marker39.dae</uri>
              <scale>0.64 0.64 0.64</scale>
            </mesh>
          </geometry>
        </visual>
        <self_collide>0</self_collide>
        <kinematic>0</kinematic>
      </link>
      <pose frame=''>2.50471 -0.04803 0 0 -0 0</pose>
    </model>
    <state world_name='default'>
      <sim_time>906 580000000</sim_time>
      <real_time>823 127409674</real_time>
      <wall_time>1528825227 928487980</wall_time>
      <iterations>72268</iterations>
      <model name='Marker15'>
        <pose frame=''>10 0.5 0.8 0 -0 0</pose>
        <scale>1 1 1</scale>
        <link name='link'>
          <pose frame=''>10 0.5 0.8 0 -0 0</pose>
          <velocity>0 0 0 0 -0 0</velocity>
          <acceleration>0 0 0 0 -0 0</acceleration>
          <wrench>0 0 0 0 -0 0</wrench>
        </link>
      </model>
      <model name='Marker16'>
        <pose frame=''>10 -0.5 0.8 0 -0 0</pose>
        <scale>1 1 1</scale>
        <link name='link'>
          <pose frame=''>10 -0.5 0.8 0 -0 0</pose>
          <velocity>0 0 0 0 -0 0</velocity>
          <acceleration>0 0 0 0 -0 0</acceleration>
          <wrench>0 0 0 0 -0 0</wrench>
        </link>
      </model>
      <model name='Marker39'>
        <pose frame=''>10 0 0.8 0 -0 0</pose>
        <scale>1 1 1</scale>
        <link name='link'>
          <pose frame=''>10 0 0.8 0 -0 0</pose>
          <velocity>0 0 0 0 -0 0</velocity>
          <acceleration>0 0 0 0 -0 0</acceleration>
          <wrench>0 0 0 0 -0 0</wrench>
        </link>
      </model>
      <model name='bebop2'>
        <pose frame=''>0.17538 -0.015832 0.909219 0 0 -0.000217</pose>
        <scale>1 1 1</scale>
        <link name='bebop2/base_link'>
          <pose frame=''>0.17538 -0.015832 0.909219 0 0 -0.000217</pose>
          <velocity>0 0 0 -1e-06 1e-06 0</velocity>
          <acceleration>-1e-06 1e-06 0 6e-06 -0 0</acceleration>
          <wrench>0 0 0 0 -0 0</wrench>
        </link>
        <link name='bebop2/imu_link'>
          <pose frame=''>0.17538 -0.015832 0.909219 0 0 -0.000217</pose>
          <velocity>0 0 0 -1e-06 1e-06 0</velocity>
          <acceleration>-1e-06 1e-06 0 6e-06 -0 0</acceleration>
          <wrench>0 0 0 0 -0 0</wrench>
        </link>
        <link name='bebop2/imugt_link'>
          <pose frame=''>0.17538 -0.015832 0.909219 0 0 -0.000217</pose>
          <velocity>0 0 0 -1e-06 1e-06 0</velocity>
          <acceleration>-1e-06 1e-06 0 6e-06 -0 0</acceleration>
          <wrench>0 0 0 0 -0 0</wrench>
        </link>
        <link name='bebop2/odometry_sensor1_link'>
          <pose frame=''>0.17538 -0.015832 0.909219 0 0 -0.000217</pose>
          <velocity>0 0 0 -1e-06 1e-06 0</velocity>
          <acceleration>-1e-06 1e-06 0 6e-06 -0 0</acceleration>
          <wrench>0 0 0 0 -0 0</wrench>
        </link>
        <link name='bebop2/odometry_sensorgt_link'>
          <pose frame=''>0.17538 -0.015832 0.909219 0 0 -0.000217</pose>
          <velocity>0 0 0 -1e-06 1e-06 0</velocity>
          <acceleration>-1e-06 1e-06 0 6e-06 -0 0</acceleration>
          <wrench>0 0 0 0 -0 0</wrench>
        </link>
        <link name='bebop2/rotor_0'>
          <pose frame=''>0.259915 -0.1302 0.904209 0 0 -0.126473</pose>
          <velocity>0 0 0 -3e-06 5e-06 1.6351</velocity>
          <acceleration>-1e-06 1e-06 0 -0.000956 8.3e-05 0</acceleration>
          <wrench>0 0 0 0 -0 0</wrench>
        </link>
        <link name='bebop2/rotor_1'>
          <pose frame=''>0.085055 0.098708 0.904209 0 -0 2.8876</pose>
          <velocity>0 0 0 -3e-06 5e-06 0.315683</velocity>
          <acceleration>-1e-06 1e-06 1e-06 -0.001126 0.000249 0</acceleration>
          <wrench>0 0 0 0 -0 0</wrench>
        </link>
        <link name='bebop2/rotor_2'>
          <pose frame=''>0.259965 0.09878 0.904209 0 -0 2.27705</pose>
          <velocity>0 0 0 1e-06 -3e-06 -1.5881</velocity>
          <acceleration>-1e-06 1e-06 1e-06 0.000444 -0.00043 0</acceleration>
          <wrench>0 0 0 0 -0 0</wrench>
        </link>
        <link name='bebop2/rotor_3'>
          <pose frame=''>0.085005 -0.130042 0.904209 0 0 -2.79909</pose>
          <velocity>0 0 0 1e-06 -2e-06 -0.364258</velocity>
          <acceleration>-1e-06 1e-06 0 -0.000448 -0.000191 -0</acceleration>
          <wrench>0 0 0 0 -0 0</wrench>
        </link>
      </model>
      <model name='ground_plane'>
        <pose frame=''>0 0 0 0 -0 0</pose>
        <scale>1 1 1</scale>
        <link name='link'>
          <pose frame=''>0 0 0 0 -0 0</pose>
          <velocity>0 0 0 0 -0 0</velocity>
          <acceleration>0 0 0 0 -0 0</acceleration>
          <wrench>0 0 0 0 -0 0</wrench>
        </link>
      </model>
      <light name='sun'>
        <pose frame=''>0 0 10 0 -0 0</pose>
      </light>
    </state>
    <gui fullscreen='0'>
      <camera name='user_camera'>
        <pose frame=''>12.8659 -4.26189 2.62411 0 0.275643 2.35619</pose>
        <view_controller>orbit</view_controller>
        <projection_type>perspective</projection_type>
      </camera>
    </gui>
    <model name='Marker16'>
      <static>1</static>
      <link name='link'>
        <visual name='visual'>
          <geometry>
            <mesh>
              <uri>model://marker16/meshes/Marker16.dae</uri>
              <scale>0.64 0.64 0.64</scale>
            </mesh>
          </geometry>
        </visual>
        <self_collide>0</self_collide>
        <kinematic>0</kinematic>
      </link>
      <pose frame=''>10.9535 -1.77555 0 0 -0 0</pose>
    </model>
    <model name='Marker15'>
      <static>1</static>
      <link name='link'>
        <visual name='visual'>
          <geometry>
            <mesh>
              <uri>model://marker15/meshes/Marker15.dae</uri>
              <scale>0.64 0.64 0.64</scale>
            </mesh>
          </geometry>
        </visual>
        <self_collide>0</self_collide>
        <kinematic>0</kinematic>
      </link>
      <pose frame=''>10.9453 -1.22966 0 0 -0 0</pose>
    </model>
  </world>
</sdf>
